<mujoco model="SN475_Rajagopal_Scaled">
  <compiler meshdir="./meshes/" inertiafromgeom="auto" angle="radian" balanceinertia="true" boundmass="0.001" boundinertia="0.001">
    <lengthrange inttotal="50" useexisting="true" />
  </compiler>
  <default>
    <joint limited="true" damping="0.5" armature="0.1" stiffness="0" />
    <geom rgba="0.8 0.6 .4 1" margin="0.001" />
    <general gainprm="5 0 0 0 0 0 0 0 0 0" ctrllimited="true" ctrlrange="-100.0 100.0"/>
  </default>
    <!-- <option timestep="0.002" -->
            <!-- integrator="implicitfast"/> -->
  <option timestep="0.001" />
  <size njmax="1000" nconmax="400" nuser_jnt="1" />
  <worldbody>
    <geom name="floor" pos="0 0 0" size="100 100 0.125" type="plane" material="MatPlane" condim="3" />
    <body name="pelvis" pos="       0        0        0.885" quat="0.7071067811865475 0.7071067811865475 0.0 0.0">
      <light mode="trackcom" directional="false" pos="0 0 4.0" dir="0 0 -1" />
      <geom name="r_pelvis" type="mesh" mesh="r_pelvis" />
      <geom name="l_pelvis" type="mesh" mesh="l_pelvis" />
      <geom name="sacrum" type="mesh" mesh="sacrum" />
      <inertial pos="-0.0759082        0        0" mass="11.5893980715774" fullinertia="0.116616 0.0988059 0.0656815        0        0        0" />
      <joint name="pelvis_tx" type="slide" pos="0 0 0" axis="       1        0        0" limited="false" range="      -5        5" ref="0" armature="0" damping="0" stiffness="0" />
      <joint name="pelvis_ty" type="slide" pos="0 0 0" axis="       0        1        0" limited="false" range="      -1        2" ref="0" armature="0" damping="0" stiffness="0" />
      <joint name="pelvis_tz" type="slide" pos="0 0 0" axis="       0        0        1" limited="false" range="      -3        3" ref="0" armature="0" damping="0" stiffness="0" />
      <joint name="pelvis_tilt" type="hinge" pos="0 0 0" axis="       0        0        1" limited="false" range=" -1.5708   1.5708" ref="0" armature="0" damping="0" stiffness="0" />
      <joint name="pelvis_list" type="hinge" pos="0 0 0" axis="       1        0        0" limited="false" range=" -1.5708   1.5708" ref="0" armature="0" damping="0" stiffness="0" />
      <joint name="pelvis_rotation" type="hinge" pos="0 0 0" axis="       0        1        0" limited="false" range=" -1.5708   1.5708" ref="0" armature="0" damping="0" stiffness="0" />
      <body name="femur_r" pos="-0.0604216 -0.0842721 0.0829514" quat="1.0 0.0 0.0 0.0">
        <geom name="r_femur" type="mesh" mesh="r_femur" />
        <inertial pos="       0 -0.155893        0" mass="5.70296029242102" fullinertia="0.069038 0.0180973 0.0728018        0        0        0" />
        <joint name="hip_flexion_r" type="hinge" pos="0 0 0" axis="       0        0        1" limited="true" range="-0.523599   2.0944" ref="0" />
        <joint name="hip_adduction_r" type="hinge" pos="0 0 0" axis="       1        0        0" limited="true" range="-0.872665 0.523599" ref="0" />
        <joint name="hip_rotation_r" type="hinge" pos="0 0 0" axis="       0        1        0" limited="true" range="-0.698132 0.698132" ref="0" />
        <body name="tibia_r" pos="0.000321678 -0.370724 -0.00110115" quat="1.0 7.240636975890137e-18 -9.456205735995121e-17 -2.960068750797159e-20">
          <geom name="r_tibia" type="mesh" mesh="r_tibia" />
          <geom name="r_fibula" type="mesh" mesh="r_fibula" />
          <inertial pos="       0 -0.178641        0" mass="2.58232270713756" fullinertia="0.0321391 0.00325217 0.0325855        0        0        0" />
          <joint name="knee_angle_r" type="hinge" pos="0 0 0" axis="-3.98373e-10 -0.0707131 -0.997497" limited="true" range="       0   2.0944" ref="0" />
          <body name="talus_r" pos="-0.00956835 -0.382734        0" quat="1.0 -6.036754011562992e-18 1.5193252867388614e-18 -2.498419531737724e-19">
            <geom name="r_talus" type="mesh" mesh="r_talus" />
            <inertial pos="       0        0        0" mass="0.047281631812007" fullinertia="0.000334355 0.000334355 0.000334355        0        0        0" />
            <joint name="ankle_angle_r" type="hinge" pos="0 0 0" axis="-0.105014 -0.174022 0.979126" limited="true" range="-0.698132 0.523599" ref="0" />
            <body name="calcn_r" pos="-0.041012 -0.0352769 0.00666014" quat="1.0 -5.320429553087796e-19 1.609289071159989e-17 -2.1848634538867752e-17">
              <geom name="r_foot" type="mesh" mesh="r_foot" />
              <inertial pos="0.0840926 0.0252278        0" mass="0.591020397650087" fullinertia="0.000468098 0.00130399 0.00137086        0        0        0" />
              <body name="toes_r" pos="0.150358 -0.00168185 0.000908201" quat="1.0 1.314867274624753e-31 -2.6810890689525335e-17 -3.939849802505862e-32">
                <geom name="r_bofoot" type="mesh" mesh="r_bofoot" />
                <inertial pos="0.0290961 0.00504556 -0.0147162" mass="0.102412014504807" fullinertia="3.34355e-05 6.68711e-05 0.000334355        0        0        0" />
              </body>
            </body>
          </body>
        </body>
      </body>
      <body name="femur_l" pos="-0.0604216 -0.0842721 -0.0829514" quat="1.0 0.0 0.0 0.0">
        <geom name="l_femur" type="mesh" mesh="l_femur" />
        <inertial pos="       0 -0.154827        0" mass="5.58677355859822" fullinertia="0.0667098 0.017487 0.0703467        0        0        0" />
        <joint name="hip_flexion_l" type="hinge" pos="0 0 0" axis="       0        0        1" limited="true" range="-0.523599   2.0944" ref="0" />
        <joint name="hip_adduction_l" type="hinge" pos="0 0 0" axis="      -1       -0       -0" limited="true" range="-0.872665 0.523599" ref="0" />
        <joint name="hip_rotation_l" type="hinge" pos="0 0 0" axis="      -0       -1       -0" limited="true" range="-0.698132 0.698132" ref="0" />
        <body name="tibia_l" pos="0.00040783 -0.368151 0.0010774" quat="1.0 -7.240636975890137e-18 9.456205735995121e-17 -2.960068750797159e-20">
          <geom name="l_tibia" type="mesh" mesh="l_tibia" />
          <geom name="l_fibula" type="mesh" mesh="l_fibula" />
          <inertial pos="       0 -0.179459        0" mass="2.61794166082064" fullinertia="0.0328813 0.00332728 0.033338        0        0        0" />
          <joint name="knee_angle_l" type="hinge" pos="0 0 0" axis="3.98373e-10 0.0707131 -0.997497" limited="true" range="       0   2.0944" ref="0" />
          <body name="talus_l" pos="-0.00961214 -0.384486        0" quat="1.0 6.036754011562992e-18 -1.5193252867388614e-18 -2.498419531737724e-19">
            <geom name="l_talus" type="mesh" mesh="l_talus" />
            <inertial pos="       0        0        0" mass="0.0453135589234355" fullinertia="0.000311483 0.000311483 0.000311483        0        0        0" />
            <joint name="ankle_angle_l" type="hinge" pos="0 0 0" axis="0.105014 0.174022 0.979126" limited="true" range="-0.698132 0.523599" ref="0" />
            <body name="calcn_l" pos="-0.0404349 -0.0347804 -0.00656642" quat="1.0 5.320429553087796e-19 -1.609289071159989e-17 -2.1848634538867752e-17">
              <geom name="l_foot" type="mesh" mesh="l_foot" />
              <inertial pos="0.0829093 0.0248728        0" mass="0.566419486542944" fullinertia="0.000436076 0.00121478 0.00127708        0        0        0" />
              <body name="toes_l" pos="0.148242 -0.00165819 -0.00089542" quat="1.0 1.314867274624753e-31 2.6810890689525335e-17 3.939849802505862e-32">
                <geom name="l_bofoot" type="mesh" mesh="l_bofoot" />
                <inertial pos="0.0286866 0.00497456 0.0145091" mass="0.0981491686281613" fullinertia="3.11483e-05 6.22966e-05 0.000311483        0        0        0" />
              </body>
            </body>
          </body>
        </body>
      </body>
      <body name="torso" pos="-0.108118 0.0875038        0" quat="1.0 0.0 0.0 0.0">
        <geom name="hat_spine" type="mesh" mesh="hat_spine" />
        <geom name="hat_jaw" type="mesh" mesh="hat_jaw" />
        <geom name="hat_skull" type="mesh" mesh="hat_skull" />
        <geom name="hat_ribs_scap" type="mesh" mesh="hat_ribs_scap" />
        <inertial pos="-0.0286665 0.305776        0" mass="18.6099511823664" fullinertia="0.933968 0.478544 0.906667        0        0        0" />
        <joint name="lumbar_extension" type="hinge" pos="0 0 0" axis="       0        0        1" limited="true" range=" -1.5708   1.5708" ref="0" />
        <joint name="lumbar_bending" type="hinge" pos="0 0 0" axis="       1        0        0" limited="true" range=" -1.5708   1.5708" ref="0" />
        <joint name="lumbar_rotation" type="hinge" pos="0 0 0" axis="       0        1        0" limited="true" range=" -1.5708   1.5708" ref="0" />
        <body name="humerus_r" pos="0.00301476 0.354987 0.162444" quat="1.0 0.0 0.0 0.0">
          <geom name="humerus_rv" type="mesh" mesh="humerus_rv" />
          <inertial pos="       0 -0.142672        0" mass="1.0542687374296" fullinertia="0.00466099 0.0016079 0.00523181        0        0        0" />
          <joint name="arm_flex_r" type="hinge" pos="0 0 0" axis="       0        0        1" limited="true" range=" -1.5708   1.5708" ref="0" />
          <joint name="arm_add_r" type="hinge" pos="0 0 0" axis="       1        0        0" limited="true" range=" -2.0944   1.5708" ref="0" />
          <joint name="arm_rot_r" type="hinge" pos="0 0 0" axis="       0        1        0" limited="true" range=" -1.5708   1.5708" ref="0" />
          <body name="ulna_r" pos="0.0113997 -0.248283 -0.00832171" quat="1.0 1.6893809785063376e-18 -6.938893903907228e-18 4.155190089080778e-20">
            <geom name="ulna_rv" type="mesh" mesh="ulna_rv" />
            <inertial pos="       0 -0.116243        0" mass="0.433345425036106" fullinertia="0.00196541 0.000410068 0.00213196        0        0        0" />
            <joint name="elbow_flex_r" type="hinge" pos="0 0 0" axis="0.226047 0.022269 0.973862" limited="true" range="       0    2.618" ref="0" />
            <body name="radius_r" pos="-0.00648801 -0.0125449 0.0251563" quat="1.0 2.301201592641875e-21 -6.933378131686372e-19 1.7489241099837954e-19">
              <geom name="radius_rv" type="mesh" mesh="radius_rv" />
              <inertial pos="       0 -0.122358        0" mass="0.50539511011462" fullinertia="0.00253969 0.000529888 0.0027549        0        0        0" />
              <body name="hand_r" pos="-0.00893079 -0.239428 0.013817" quat="1.0 0.0 8.407790785948892e-45 0.0">
                <geom name="pisiform_rvs" type="mesh" mesh="pisiform_rvs" />
                <geom name="lunate_rvs" type="mesh" mesh="lunate_rvs" />
                <geom name="scaphoid_rvs" type="mesh" mesh="scaphoid_rvs" />
                <geom name="triquetrum_rvs" type="mesh" mesh="triquetrum_rvs" />
                <geom name="hamate_rvs" type="mesh" mesh="hamate_rvs" />
                <geom name="capitate_rvs" type="mesh" mesh="capitate_rvs" />
                <geom name="trapezoid_rvs" type="mesh" mesh="trapezoid_rvs" />
                <geom name="trapezium_rvs" type="mesh" mesh="trapezium_rvs" />
                <geom name="metacarpal2_rvs" type="mesh" mesh="metacarpal2_rvs" />
                <geom name="index_proximal_rvs" type="mesh" mesh="index_proximal_rvs" />
                <geom name="index_medial_rvs" type="mesh" mesh="index_medial_rvs" />
                <geom name="index_distal_rvs" type="mesh" mesh="index_distal_rvs" />
                <geom name="metacarpal3_rvs" type="mesh" mesh="metacarpal3_rvs" />
                <geom name="middle_proximal_rvs" type="mesh" mesh="middle_proximal_rvs" />
                <geom name="middle_medial_rvs" type="mesh" mesh="middle_medial_rvs" />
                <geom name="middle_distal_rvs" type="mesh" mesh="middle_distal_rvs" />
                <geom name="metacarpal4_rvs" type="mesh" mesh="metacarpal4_rvs" />
                <geom name="ring_proximal_rvs" type="mesh" mesh="ring_proximal_rvs" />
                <geom name="ring_medial_rvs" type="mesh" mesh="ring_medial_rvs" />
                <geom name="ring_distal_rvs" type="mesh" mesh="ring_distal_rvs" />
                <geom name="metacarpal5_rvs" type="mesh" mesh="metacarpal5_rvs" />
                <geom name="little_proximal_rvs" type="mesh" mesh="little_proximal_rvs" />
                <geom name="little_medial_rvs" type="mesh" mesh="little_medial_rvs" />
                <geom name="little_distal_rvs" type="mesh" mesh="little_distal_rvs" />
                <geom name="metacarpal1_rvs" type="mesh" mesh="metacarpal1_rvs" />
                <geom name="thumb_proximal_rvs" type="mesh" mesh="thumb_proximal_rvs" />
                <geom name="thumb_distal_rvs" type="mesh" mesh="thumb_distal_rvs" />
                <inertial pos="       0 -0.0639237        0" mass="0.300919501256944" fullinertia="0.000517033 0.000317059 0.000776708        0        0        0" />
              </body>
            </body>
          </body>
        </body>
        <body name="humerus_l" pos="0.00301476 0.354987 -0.162444" quat="1.0 0.0 0.0 0.0">
          <geom name="humerus_lv" type="mesh" mesh="humerus_lv" />
          <inertial pos="       0 -0.143927        0" mass="1.0823274511379" fullinertia="0.00486957 0.00167985 0.00546593        0        0        0" />
          <joint name="arm_flex_l" type="hinge" pos="0 0 0" axis="       0        0        1" limited="true" range=" -1.5708   1.5708" ref="0" />
          <joint name="arm_add_l" type="hinge" pos="0 0 0" axis="      -1        0        0" limited="true" range=" -2.0944   1.5708" ref="0" />
          <joint name="arm_rot_l" type="hinge" pos="0 0 0" axis="       0       -1        0" limited="true" range=" -1.5708   1.5708" ref="0" />
          <body name="ulna_l" pos="  0.0115 -0.250467 0.00839489" quat="1.0 -1.6893809785063376e-18 6.938893903907228e-18 4.155190089080778e-20">
            <geom name="ulna_lv" type="mesh" mesh="ulna_lv" />
            <inertial pos="       0 -0.113553        0" mass="0.403946352717867" fullinertia="0.00174824 0.000364758 0.00189639        0        0        0" />
            <joint name="elbow_flex_l" type="hinge" pos="0 0 0" axis="-0.226047 -0.022269 0.973862" limited="true" range="       0    2.618" ref="0" />
            <body name="radius_l" pos="-0.00633784 -0.0122545 -0.0245741" quat="1.0 -2.301201592641875e-21 6.933378131686372e-19 1.7489241099837954e-19">
              <geom name="radius_lv" type="mesh" mesh="radius_lv" />
              <inertial pos="       0 -0.121639        0" mass="0.496534260946311" fullinertia="0.00246591 0.000514495 0.00267487        0        0        0" />
              <body name="hand_l" pos="-0.00887829 -0.23802 -0.0137358" quat="1.0 0.0 8.407790785948892e-45 0.0">
                <geom name="pisiform_lvs" type="mesh" mesh="pisiform_lvs" />
                <geom name="lunate_lvs" type="mesh" mesh="lunate_lvs" />
                <geom name="scaphoid_lvs" type="mesh" mesh="scaphoid_lvs" />
                <geom name="triquetrum_lvs" type="mesh" mesh="triquetrum_lvs" />
                <geom name="hamate_lvs" type="mesh" mesh="hamate_lvs" />
                <geom name="capitate_lvs" type="mesh" mesh="capitate_lvs" />
                <geom name="trapezoid_lvs" type="mesh" mesh="trapezoid_lvs" />
                <geom name="trapezium_lvs" type="mesh" mesh="trapezium_lvs" />
                <geom name="metacarpal2_lvs" type="mesh" mesh="metacarpal2_lvs" />
                <geom name="index_proximal_lvs" type="mesh" mesh="index_proximal_lvs" />
                <geom name="index_medial_lvs" type="mesh" mesh="index_medial_lvs" />
                <geom name="index_distal_lvs" type="mesh" mesh="index_distal_lvs" />
                <geom name="metacarpal3_lvs" type="mesh" mesh="metacarpal3_lvs" />
                <geom name="middle_proximal_lvs" type="mesh" mesh="middle_proximal_lvs" />
                <geom name="middle_medial_lvs" type="mesh" mesh="middle_medial_lvs" />
                <geom name="middle_distal_lvs" type="mesh" mesh="middle_distal_lvs" />
                <geom name="metacarpal4_lvs" type="mesh" mesh="metacarpal4_lvs" />
                <geom name="ring_proximal_lvs" type="mesh" mesh="ring_proximal_lvs" />
                <geom name="ring_medial_lvs" type="mesh" mesh="ring_medial_lvs" />
                <geom name="ring_distal_lvs" type="mesh" mesh="ring_distal_lvs" />
                <geom name="metacarpal5_lvs" type="mesh" mesh="metacarpal5_lvs" />
                <geom name="little_proximal_lvs" type="mesh" mesh="little_proximal_lvs" />
                <geom name="little_medial_lvs" type="mesh" mesh="little_medial_lvs" />
                <geom name="little_distal_lvs" type="mesh" mesh="little_distal_lvs" />
                <geom name="metacarpal1_lvs" type="mesh" mesh="metacarpal1_lvs" />
                <geom name="thumb_proximal_lvs" type="mesh" mesh="thumb_proximal_lvs" />
                <geom name="thumb_distal_lvs" type="mesh" mesh="thumb_distal_lvs" />
                <inertial pos="       0 -0.0731465        0" mass="0.450863643098478" fullinertia="0.00101432 0.000622012 0.00152376        0        0        0" />
              </body>
            </body>
          </body>
        </body>
      </body>
    </body>

    <body name="softbody_l_foot" pos="-0.22 0 0.71">
      <body name="softbody_l_foot_1" pos="0.0989598 0.0651699 -1.62567">
        <inertial pos="0 0 0" mass="0.0930266" diaginertia="0.001 0.001 0.001"/>
        <!-- <joint name="joint_softbody_l_foot_43" pos="0 0 0" axis="1 0 0" type="slide"/> -->
      </body>
      <body name="softbody_l_foot_43" pos="0.0828655 0.0875301 -1.67632">
        <inertial pos="0 0 0" mass="0.0930266" diaginertia="0.001 0.001 0.001"/>
        <!-- <joint name="joint_softbody_l_foot_1" pos="0 0 0" axis="1 0 0" type="slide"/> -->
      </body>
    </body>

    <camera name="for_testing" pos="0 0 0" euler="0 0 0" />
  </worldbody>
  <asset>
    <mesh name="r_pelvis" file="rajagopal/r_pelvis.stl" scale=" 1.07367  1.07367  1.07367" />
    <mesh name="l_pelvis" file="rajagopal/l_pelvis.stl" scale=" 1.07367  1.07367  1.07367" />
    <mesh name="sacrum" file="rajagopal/sacrum.stl" scale=" 1.07367  1.07367  1.07367" />
    <mesh name="r_femur" file="rajagopal/r_femur.stl" scale="0.917018 0.917018 0.917018" />
    <mesh name="r_tibia" file="rajagopal/r_tibia.stl" scale="0.956835 0.956835 0.956835" />
    <mesh name="r_fibula" file="rajagopal/r_fibula.stl" scale="0.956835 0.956835 0.956835" />
    <mesh name="r_talus" file="rajagopal/r_talus.stl" scale="0.840926 0.840926 0.840926" />
    <mesh name="r_foot" file="rajagopal/r_foot.stl" scale="0.840926 0.840926 0.840926" />
    <mesh name="r_bofoot" file="rajagopal/r_bofoot.stl" scale="0.840926 0.840926 0.840926" />
    <mesh name="l_femur" file="rajagopal/l_femur.stl" scale="0.910748 0.910748 0.910748" />
    <mesh name="l_tibia" file="rajagopal/l_tibia.stl" scale="0.961214 0.961214 0.961214" />
    <mesh name="l_fibula" file="rajagopal/l_fibula.stl" scale="0.961214 0.961214 0.961214" />
    <mesh name="l_talus" file="rajagopal/l_talus.stl" scale="0.829093 0.829093 0.829093" />
    <mesh name="l_foot" file="rajagopal/l_foot.stl" scale="0.829093 0.829093 0.829093" />
    <mesh name="l_bofoot" file="rajagopal/l_bofoot.stl" scale="0.829093 0.829093 0.829093" />
    <mesh name="hat_spine" file="rajagopal/hat_spine.stl" scale="0.955551 0.955551 0.955551" />
    <mesh name="hat_jaw" file="rajagopal/hat_jaw.stl" scale="0.955551 0.955551 0.955551" />
    <mesh name="hat_skull" file="rajagopal/hat_skull.stl" scale="0.955551 0.955551 0.955551" />
    <mesh name="hat_ribs_scap" file="rajagopal/hat_ribs_scap.stl" scale="0.955551 0.955551 0.955551" />
    <mesh name="humerus_rv" file="rajagopal/humerus_rv.stl" scale="0.867296 0.867296 0.867296" />
    <mesh name="ulna_rv" file="rajagopal/ulna_rv.stl" scale="0.964472 0.964472 0.964472" />
    <mesh name="radius_rv" file="rajagopal/radius_rv.stl" scale=" 1.01521  1.01521  1.01521" />
    <mesh name="pisiform_rvs" file="rajagopal/pisiform_rvs.stl" scale="0.797932 0.797932 0.797932" />
    <mesh name="lunate_rvs" file="rajagopal/lunate_rvs.stl" scale="0.797932 0.797932 0.797932" />
    <mesh name="scaphoid_rvs" file="rajagopal/scaphoid_rvs.stl" scale="0.797932 0.797932 0.797932" />
    <mesh name="triquetrum_rvs" file="rajagopal/triquetrum_rvs.stl" scale="0.797932 0.797932 0.797932" />
    <mesh name="hamate_rvs" file="rajagopal/hamate_rvs.stl" scale="0.797932 0.797932 0.797932" />
    <mesh name="capitate_rvs" file="rajagopal/capitate_rvs.stl" scale="0.797932 0.797932 0.797932" />
    <mesh name="trapezoid_rvs" file="rajagopal/trapezoid_rvs.stl" scale="0.797932 0.797932 0.797932" />
    <mesh name="trapezium_rvs" file="rajagopal/trapezium_rvs.stl" scale="0.797932 0.797932 0.797932" />
    <mesh name="metacarpal2_rvs" file="rajagopal/metacarpal2_rvs.stl" scale="0.797932 0.797932 0.797932" />
    <mesh name="index_proximal_rvs" file="rajagopal/index_proximal_rvs.stl" scale="0.797932 0.797932 0.797932" />
    <mesh name="index_medial_rvs" file="rajagopal/index_medial_rvs.stl" scale="0.797932 0.797932 0.797932" />
    <mesh name="index_distal_rvs" file="rajagopal/index_distal_rvs.stl" scale="0.797932 0.797932 0.797932" />
    <mesh name="metacarpal3_rvs" file="rajagopal/metacarpal3_rvs.stl" scale="0.797932 0.797932 0.797932" />
    <mesh name="middle_proximal_rvs" file="rajagopal/middle_proximal_rvs.stl" scale="0.797932 0.797932 0.797932" />
    <mesh name="middle_medial_rvs" file="rajagopal/middle_medial_rvs.stl" scale="0.797932 0.797932 0.797932" />
    <mesh name="middle_distal_rvs" file="rajagopal/middle_distal_rvs.stl" scale="0.797932 0.797932 0.797932" />
    <mesh name="metacarpal4_rvs" file="rajagopal/metacarpal4_rvs.stl" scale="0.797932 0.797932 0.797932" />
    <mesh name="ring_proximal_rvs" file="rajagopal/ring_proximal_rvs.stl" scale="0.797932 0.797932 0.797932" />
    <mesh name="ring_medial_rvs" file="rajagopal/ring_medial_rvs.stl" scale="0.797932 0.797932 0.797932" />
    <mesh name="ring_distal_rvs" file="rajagopal/ring_distal_rvs.stl" scale="0.797932 0.797932 0.797932" />
    <mesh name="metacarpal5_rvs" file="rajagopal/metacarpal5_rvs.stl" scale="0.797932 0.797932 0.797932" />
    <mesh name="little_proximal_rvs" file="rajagopal/little_proximal_rvs.stl" scale="0.797932 0.797932 0.797932" />
    <mesh name="little_medial_rvs" file="rajagopal/little_medial_rvs.stl" scale="0.797932 0.797932 0.797932" />
    <mesh name="little_distal_rvs" file="rajagopal/little_distal_rvs.stl" scale="0.797932 0.797932 0.797932" />
    <mesh name="metacarpal1_rvs" file="rajagopal/metacarpal1_rvs.stl" scale="0.797932 0.797932 0.797932" />
    <mesh name="thumb_proximal_rvs" file="rajagopal/thumb_proximal_rvs.stl" scale="0.797932 0.797932 0.797932" />
    <mesh name="thumb_distal_rvs" file="rajagopal/thumb_distal_rvs.stl" scale="0.797932 0.797932 0.797932" />
    <mesh name="humerus_lv" file="rajagopal/humerus_lv.stl" scale="0.874923 0.874923 0.874923" />
    <mesh name="ulna_lv" file="rajagopal/ulna_lv.stl" scale="0.942149 0.942149 0.942149" />
    <mesh name="radius_lv" file="rajagopal/radius_lv.stl" scale=" 1.00924  1.00924  1.00924" />
    <mesh name="pisiform_lvs" file="rajagopal/pisiform_lvs.stl" scale="0.913056 0.913056 0.913056" />
    <mesh name="lunate_lvs" file="rajagopal/lunate_lvs.stl" scale="0.913056 0.913056 0.913056" />
    <mesh name="scaphoid_lvs" file="rajagopal/scaphoid_lvs.stl" scale="0.913056 0.913056 0.913056" />
    <mesh name="triquetrum_lvs" file="rajagopal/triquetrum_lvs.stl" scale="0.913056 0.913056 0.913056" />
    <mesh name="hamate_lvs" file="rajagopal/hamate_lvs.stl" scale="0.913056 0.913056 0.913056" />
    <mesh name="capitate_lvs" file="rajagopal/capitate_lvs.stl" scale="0.913056 0.913056 0.913056" />
    <mesh name="trapezoid_lvs" file="rajagopal/trapezoid_lvs.stl" scale="0.913056 0.913056 0.913056" />
    <mesh name="trapezium_lvs" file="rajagopal/trapezium_lvs.stl" scale="0.913056 0.913056 0.913056" />
    <mesh name="metacarpal2_lvs" file="rajagopal/metacarpal2_lvs.stl" scale="0.913056 0.913056 0.913056" />
    <mesh name="index_proximal_lvs" file="rajagopal/index_proximal_lvs.stl" scale="0.913056 0.913056 0.913056" />
    <mesh name="index_medial_lvs" file="rajagopal/index_medial_lvs.stl" scale="0.913056 0.913056 0.913056" />
    <mesh name="index_distal_lvs" file="rajagopal/index_distal_lvs.stl" scale="0.913056 0.913056 0.913056" />
    <mesh name="metacarpal3_lvs" file="rajagopal/metacarpal3_lvs.stl" scale="0.913056 0.913056 0.913056" />
    <mesh name="middle_proximal_lvs" file="rajagopal/middle_proximal_lvs.stl" scale="0.913056 0.913056 0.913056" />
    <mesh name="middle_medial_lvs" file="rajagopal/middle_medial_lvs.stl" scale="0.913056 0.913056 0.913056" />
    <mesh name="middle_distal_lvs" file="rajagopal/middle_distal_lvs.stl" scale="0.913056 0.913056 0.913056" />
    <mesh name="metacarpal4_lvs" file="rajagopal/metacarpal4_lvs.stl" scale="0.913056 0.913056 0.913056" />
    <mesh name="ring_proximal_lvs" file="rajagopal/ring_proximal_lvs.stl" scale="0.913056 0.913056 0.913056" />
    <mesh name="ring_medial_lvs" file="rajagopal/ring_medial_lvs.stl" scale="0.913056 0.913056 0.913056" />
    <mesh name="ring_distal_lvs" file="rajagopal/ring_distal_lvs.stl" scale="0.913056 0.913056 0.913056" />
    <mesh name="metacarpal5_lvs" file="rajagopal/metacarpal5_lvs.stl" scale="0.913056 0.913056 0.913056" />
    <mesh name="little_proximal_lvs" file="rajagopal/little_proximal_lvs.stl" scale="0.913056 0.913056 0.913056" />
    <mesh name="little_medial_lvs" file="rajagopal/little_medial_lvs.stl" scale="0.913056 0.913056 0.913056" />
    <mesh name="little_distal_lvs" file="rajagopal/little_distal_lvs.stl" scale="0.913056 0.913056 0.913056" />
    <mesh name="metacarpal1_lvs" file="rajagopal/metacarpal1_lvs.stl" scale="0.913056 0.913056 0.913056" />
    <mesh name="thumb_proximal_lvs" file="rajagopal/thumb_proximal_lvs.stl" scale="0.913056 0.913056 0.913056" />
    <mesh name="thumb_distal_lvs" file="rajagopal/thumb_distal_lvs.stl" scale="0.913056 0.913056 0.913056" />
    <texture name="texplane" type="2d" builtin="checker" rgb1=".2 .3 .4" rgb2=".1 0.15 0.2" width="100" height="100" />
    <material name="MatPlane" reflectance="0.0" texture="texplane" texrepeat="1 1" texuniform="true" />
  </asset>
  <actuator>
    <!-- Root -->
    <motor name="pelvis_tz" joint="pelvis_tz"/>
    <motor name="pelvis_ty" joint="pelvis_ty"/>
    <motor name="pelvis_tx" joint="pelvis_tx"/>
    <motor name="pelvis_tilt" joint="pelvis_tilt"/>
    <motor name="pelvis_list" joint="pelvis_list"/>
    <motor name="pelvis_rotation" joint="pelvis_rotation"/>

    <!-- Right Leg -->
    <motor name="hip_flexion_r" joint="hip_flexion_r"/>
    <motor name="hip_adduction_r" joint="hip_adduction_r"/>
    <motor name="hip_rotation_r" joint="hip_rotation_r"/>
    <motor name="knee_angle_r" joint="knee_angle_r"/>
    <motor name="ankle_angle_r" joint="ankle_angle_r"/>

    <!-- Left Leg -->
    <motor name="hip_flexion_l" joint="hip_flexion_l"/>
    <motor name="hip_adduction_l" joint="hip_adduction_l"/>
    <motor name="hip_rotation_l" joint="hip_rotation_l"/>
    <motor name="knee_angle_l" joint="knee_angle_l"/>
    <motor name="ankle_angle_l" joint="ankle_angle_l"/>

    <!-- Torso -->
    <motor name="lumbar_extension" joint="lumbar_extension" />
    <motor name="lumbar_bending" joint="lumbar_bending"/>
    <motor name="lumbar_rotation" joint="lumbar_rotation"/>

    <!-- Right Arm -->
    <motor name="arm_flex_r" joint="arm_flex_r"/>
    <motor name="arm_add_r" joint="arm_add_r"/>
    <motor name="arm_rot_r" joint="arm_rot_r"/>
    <motor name="elbow_flex_r" joint="elbow_flex_r"/>

    <!-- Left Arm -->
    <motor name="arm_flex_l" joint="arm_flex_l"/>
    <motor name="arm_add_l" joint="arm_add_l" />
    <motor name="arm_rot_l" joint="arm_rot_l" />
    <motor name="elbow_flex_l" joint="elbow_flex_l" />
  </actuator>
  <equality>
    <weld name="origin_to_worldbody" body1="pelvis" active="false" />
  </equality>
</mujoco>
